Traceback (most recent call last):
  File "/Users/yingsun/Library/Caches/pypoetry/virtualenvs/pgo-npc-9XK8Woi6-py3.10/lib/python3.10/site-packages/torch/utils/data/dataloader.py", line 1251, in _try_get_data
    data = self._data_queue.get(timeout=timeout)
  File "/Users/yingsun/.pyenv/versions/3.10.9/lib/python3.10/multiprocessing/queues.py", line 113, in get
    if not self._poll(timeout):
  File "/Users/yingsun/.pyenv/versions/3.10.9/lib/python3.10/multiprocessing/connection.py", line 257, in poll
    return self._poll(timeout)
  File "/Users/yingsun/.pyenv/versions/3.10.9/lib/python3.10/multiprocessing/connection.py", line 424, in _poll
    r = wait([self], timeout)
  File "/Users/yingsun/.pyenv/versions/3.10.9/lib/python3.10/multiprocessing/connection.py", line 931, in wait
    ready = selector.select(timeout)
  File "/Users/yingsun/.pyenv/versions/3.10.9/lib/python3.10/selectors.py", line 416, in select
    fd_event_list = self._selector.poll(timeout)
  File "/Users/yingsun/Library/Caches/pypoetry/virtualenvs/pgo-npc-9XK8Woi6-py3.10/lib/python3.10/site-packages/torch/utils/data/_utils/signal_handling.py", line 73, in handler
    _error_if_any_worker_fails()
RuntimeError: DataLoader worker (pid 9382) exited unexpectedly with exit code 1. Details are lost due to multiprocessing. Rerunning with num_workers=0 may give better error trace.

The above exception was the direct cause of the following exception:

Traceback (most recent call last):
  File "/Users/yingsun/NanoLLM/test_wandb.py", line 151, in <module>
    for step, (images, labels) in enumerate(train_dl):
  File "/Users/yingsun/Library/Caches/pypoetry/virtualenvs/pgo-npc-9XK8Woi6-py3.10/lib/python3.10/site-packages/torch/utils/data/dataloader.py", line 708, in __next__
    data = self._next_data()
  File "/Users/yingsun/Library/Caches/pypoetry/virtualenvs/pgo-npc-9XK8Woi6-py3.10/lib/python3.10/site-packages/torch/utils/data/dataloader.py", line 1458, in _next_data
    idx, data = self._get_data()
  File "/Users/yingsun/Library/Caches/pypoetry/virtualenvs/pgo-npc-9XK8Woi6-py3.10/lib/python3.10/site-packages/torch/utils/data/dataloader.py", line 1420, in _get_data
    success, data = self._try_get_data()
  File "/Users/yingsun/Library/Caches/pypoetry/virtualenvs/pgo-npc-9XK8Woi6-py3.10/lib/python3.10/site-packages/torch/utils/data/dataloader.py", line 1264, in _try_get_data
    raise RuntimeError(
RuntimeError: DataLoader worker (pid(s) 9382) exited unexpectedly
Traceback (most recent call last):
  File "/Users/yingsun/Library/Caches/pypoetry/virtualenvs/pgo-npc-9XK8Woi6-py3.10/lib/python3.10/site-packages/torch/utils/data/dataloader.py", line 1251, in _try_get_data
    data = self._data_queue.get(timeout=timeout)
  File "/Users/yingsun/.pyenv/versions/3.10.9/lib/python3.10/multiprocessing/queues.py", line 113, in get
    if not self._poll(timeout):
  File "/Users/yingsun/.pyenv/versions/3.10.9/lib/python3.10/multiprocessing/connection.py", line 257, in poll
    return self._poll(timeout)
  File "/Users/yingsun/.pyenv/versions/3.10.9/lib/python3.10/multiprocessing/connection.py", line 424, in _poll
    r = wait([self], timeout)
  File "/Users/yingsun/.pyenv/versions/3.10.9/lib/python3.10/multiprocessing/connection.py", line 931, in wait
    ready = selector.select(timeout)
  File "/Users/yingsun/.pyenv/versions/3.10.9/lib/python3.10/selectors.py", line 416, in select
    fd_event_list = self._selector.poll(timeout)
  File "/Users/yingsun/Library/Caches/pypoetry/virtualenvs/pgo-npc-9XK8Woi6-py3.10/lib/python3.10/site-packages/torch/utils/data/_utils/signal_handling.py", line 73, in handler
    _error_if_any_worker_fails()
RuntimeError: DataLoader worker (pid 9382) exited unexpectedly with exit code 1. Details are lost due to multiprocessing. Rerunning with num_workers=0 may give better error trace.

The above exception was the direct cause of the following exception:

Traceback (most recent call last):
  File "/Users/yingsun/NanoLLM/test_wandb.py", line 151, in <module>
    for step, (images, labels) in enumerate(train_dl):
  File "/Users/yingsun/Library/Caches/pypoetry/virtualenvs/pgo-npc-9XK8Woi6-py3.10/lib/python3.10/site-packages/torch/utils/data/dataloader.py", line 708, in __next__
    data = self._next_data()
  File "/Users/yingsun/Library/Caches/pypoetry/virtualenvs/pgo-npc-9XK8Woi6-py3.10/lib/python3.10/site-packages/torch/utils/data/dataloader.py", line 1458, in _next_data
    idx, data = self._get_data()
  File "/Users/yingsun/Library/Caches/pypoetry/virtualenvs/pgo-npc-9XK8Woi6-py3.10/lib/python3.10/site-packages/torch/utils/data/dataloader.py", line 1420, in _get_data
    success, data = self._try_get_data()
  File "/Users/yingsun/Library/Caches/pypoetry/virtualenvs/pgo-npc-9XK8Woi6-py3.10/lib/python3.10/site-packages/torch/utils/data/dataloader.py", line 1264, in _try_get_data
    raise RuntimeError(
RuntimeError: DataLoader worker (pid(s) 9382) exited unexpectedly
